<?xml version="1.0"?>
<sdf version="1.5">
    <model name="Schleicher_ASK_21">
        <self_collide> true </self_collide>
        <enable_wind> true </enable_wind>
        <!-- ALL LINKS -->
        <link name="Fuselage">
            <pose> 0 0 0.5 0 0 0 </pose>
            <collision name="Fuselage_collision">
                <geometry>
                    <!--box> <size> 1 8 2 </size> </box-->
                    <mesh>
                        <uri> model://Glider/meshes/Fuselage.dae</uri>
                    </mesh>
                </geometry>
            </collision>
            <visual name="Fuselage_visual">
                <geometry>
                    <mesh>
                        <uri> model://Glider/meshes/Fuselage.dae</uri>
                    </mesh>
                </geometry>
            </visual>
            <inertial>
                <mass>1.2571</mass>
                <pose>-0.00004958 0.391 0.031 0 0 0</pose>
                <inertia>
                    <ixx>0.065625</ixx>
                    <iyy>0.0014583</iyy>
                    <izz>0.065625</izz>
                    <ixy>8.7e-07</ixy>
                    <ixz>-2.65e-06</ixz>
                    <iyz>-0.004375</iyz>
                </inertia>
            </inertial>
            <sensor type="imu" name="IMU_Fuselage">
                <always_on>true</always_on>
                <update_rate>50</update_rate>
                <frame name="IMU_frame">
                    <pose>-0.00004958 0.391 0.031 0 0 0</pose>
                </frame>
            </sensor>
            <!--<sensor type="magnetometer" name="Magn_Fuselage">-->
            <!--<always_on> true </always_on>-->
            <!--<update_rate> 50 </update_rate>-->
            <!--<frame name="Magn_frame">-->
            <!--<pose>-0.00004958 0.391 0.031 0 0 0</pose>-->
            <!--</frame>-->
            <!--</sensor>-->
        </link>
        <link name="Tailplane">
            <pose> 0 0 0.5 0 0 0 </pose>
            <collision name="Tailplane_collision">
                <geometry>
                    <mesh>
                        <uri> model://Glider/meshes/Tailplane.dae</uri>
                    </mesh>
                </geometry>
            </collision>
            <visual name="Tailplane_visual">
                <geometry>
                    <mesh>
                        <uri> model://Glider/meshes/Tailplane.dae</uri>
                    </mesh>
                </geometry>
            </visual>
            <inertial>
                <mass>0.029</mass>
                <pose>0 0.986 0.203 0 0 0</pose>
                <inertia>
                    <ixx>0.000005792</ixx>
                    <iyy>0.0002874</iyy>
                    <izz>0.0002926</izz>
                    <ixy>0</ixy>
                    <ixz>0</ixz>
                    <iyz>0.00000009074</iyz>
                </inertia>
            </inertial>
        </link>
        <link name="Wing">
            <pose> 0 0 0.5 0 0 0 </pose>
            <collision name="Wing_collision">
                <geometry>
                    <mesh>
                        <uri> model://Glider/meshes/Wing.dae</uri>
                    </mesh>
                </geometry>
            </collision>
            <visual name="Wing_visual">
                <geometry>
                    <mesh>
                        <uri> model://Glider/meshes/Wing.dae</uri>
                    </mesh>
                </geometry>
            </visual>
            <inertial>
                <mass>0.665</mass>
                <pose>0 0.397 0.066 0 0 0</pose>
                <inertia>
                    <ixx>0.0011</ixx>
                    <iyy>0.1259</iyy>
                    <izz>0.1265</izz>
                    <ixy>0</ixy>
                    <ixz>0</ixz>
                    <iyz>0.00016016</iyz>
                </inertia>
            </inertial>
        </link>
        <link name="Elevator">
            <pose>0 0 0.5 0 0 0 </pose>
            <collision name="Elevator_collision">
                <geometry>
                    <!--box> <size> 1 8 2 </size> </box-->
                    <mesh>
                        <uri> model://Glider/meshes/Elevator.dae</uri>
                    </mesh>
                </geometry>
            </collision>
            <visual name="Elevator_visual">
                <geometry>
                    <mesh>
                        <uri> model://Glider/meshes/Elevator.dae</uri>
                    </mesh>
                </geometry>
            </visual>
            <inertial>
                <mass>0.009</mass>
                <pose>0 1.019 0.202 0 0 0</pose>
                <inertia>
                    <ixx>0.0000003445</ixx>
                    <iyy>0.00009298</iyy>
                    <izz>0.00009329</izz>
                    <ixy>0</ixy>
                    <ixz>0</ixz>
                    <iyz>0.00000001638</iyz>
                </inertia>
            </inertial>
        </link>
        <link name="Rudder">
            <pose> 0 0 0.5 0 0 0 </pose>
            <collision name="Rudder_collision">
                <geometry>
                    <!--box> <size> 1 8 2 </size> </box-->
                    <mesh>
                        <uri> model://Glider/meshes/Rudder.dae</uri>
                    </mesh>
                </geometry>
            </collision>
            <visual name="Rudder_visual">
                <geometry>
                    <mesh>
                        <uri> model://Glider/meshes/Rudder.dae</uri>
                    </mesh>
                </geometry>
            </visual>
            <inertial>
                <mass>0.008</mass>
                <pose>0 1.037 0.112 0 0 0</pose>
                <inertia>
                    <ixx>0.00001637</ixx>
                    <iyy>0.00001575</iyy>
                    <izz>0.0000006934</izz>
                    <ixy>0</ixy>
                    <ixz>0.00000000005498</ixz>
                    <iyz>-0.000000697</iyz>
                </inertia>
            </inertial>
        </link>
        <link name="LeftAileron">
            <pose> 0 0 0.5 0 0 0 </pose>
            <collision name="LeftAileron_collision">
                <geometry>
                    <!--box> <size> 1 8 2 </size> </box-->
                    <mesh>
                        <uri> model://Glider/meshes/LeftAileron.dae</uri>
                    </mesh>
                </geometry>
            </collision>
            <visual name="LeftAileron_visual">
                <geometry>
                    <mesh>
                        <uri> model://Glider/meshes/LeftAileron.dae</uri>
                    </mesh>
                </geometry>
            </visual>
            <inertial>
                <mass>0.012</mass>
                <pose>0.808 0.413 0.094 0 0 0</pose>
                <inertia>
                    <ixx>0.000002678</ixx>
                    <iyy>0.0001171</iyy>
                    <izz>0.0001186</izz>
                    <ixy>0.00001383</ixy>
                    <ixz>-0.00000839</ixz>
                    <iyz>0.000001042</iyz>
                </inertia>
            </inertial>
        </link>
        <link name="RightAileron">
            <pose> 0 0 0.5 0 0 0 </pose>
            <collision name="RightAileron_collision">
                <geometry>
                    <!--box> <size> 1 8 2 </size> </box-->
                    <mesh>
                        <uri> model://Glider/meshes/RightAileron.dae</uri>
                    </mesh>
                </geometry>
            </collision>
            <visual name="RightAileron_visual">
                <geometry>
                    <mesh>
                        <uri> model://Glider/meshes/RightAileron.dae</uri>
                    </mesh>
                </geometry>
            </visual>
            <inertial>
                <mass>0.012</mass>
                <pose>-0.808 0.413 0.094 0 0 0</pose>
                <inertia>
                    <ixx>0.000002678</ixx>
                    <iyy>0.0001171</iyy>
                    <izz>0.0001186</izz>
                    <ixy>-0.00001383</ixy>
                    <ixz>0.00000839</ixz>
                    <iyz>0.000001042</iyz>
                </inertia>
            </inertial>
        </link>
        <!-- ALL JOINTS -->
        <joint type="fixed" name="Joint_Fuselage+Tailplane">
            <parent>Fuselage</parent>
            <child>Tailplane</child>
        </joint>
        <joint type="fixed" name="Joint_Fuselage+Wing">
            <parent>Fuselage</parent>
            <child>Wing</child>
        </joint>
        <joint type="revolute" name="Joint_Tailplane+Elevator">
            <pose>-0.189 1.013 0.203 0 0 0</pose>
            <parent>Tailplane</parent>
            <child>Elevator</child>
            <axis>
                <xyz>1 0 0</xyz>
                <limit>
                    <lower>-0.2</lower>
                    <upper>1</upper>
                </limit>
                <dynamics>
                    <damping>0.0001</damping>
                </dynamics>
            </axis>
        </joint>
        <joint type="revolute" name="Joint_Fuselage+Rudder">
            <parent>Fuselage</parent>
            <child>Rudder</child>
            <pose>0 1.016 0.053 0 0 0</pose>
            <axis>
                <xyz>0 0.069008 0.997616</xyz>
                <limit>
                    <lower>-1</lower>
                    <upper>1</upper>
                </limit>
                <dynamics>
                    <damping>0.0001</damping>
                </dynamics>
            </axis>
        </joint>
        <joint type="revolute" name="Joint_Wing+LeftAileron">
            <parent>Wing</parent>
            <child>LeftAileron</child>
            <pose>0.645 0.426 0.083 0 0 0</pose>
            <axis>
                <xyz>0.990864 -0.114803 0.070767</xyz>
                <limit>
                    <lower>-1</lower>
                    <upper>1</upper>
                </limit>
                <dynamics>
                    <damping>0.0001</damping>
                </dynamics>
            </axis>
        </joint>
        <joint type="revolute" name="Joint_Wing+RightAileron">
            <parent>Wing</parent>
            <child>RightAileron</child>
            <pose>-0.645 0.426 0.083 0 0 0</pose>
            <axis>
                <xyz>0.990864 0.114803 -0.070767</xyz>
                <limit>
                    <lower>-1</lower>
                    <upper>1</upper>
                </limit>
                <dynamics>
                    <damping>0.0001</damping>
                </dynamics>
            </axis>
        </joint>

        <!-- Plugins -->


        <plugin name="GliderPlugin" filename="cmake-build-debug/libglider.so"/>
        <!--plugin name="{$modelName}_Wing" filename="libLiftDragPlugin.so">
          <a0>0.1</a0>
          <cla>0.100</cla>
          <cda>0.01</cda>
          <cma>0.00</cma>
          <alpha_stall>0.2</alpha_stall>
          <cla_stall>-0.2</cla_stall>
          <cda_stall>1.0</cda_stall>
          <cma_stall>0.0</cma_stall>
          <cp>0.0 0.5 0</cp>
          <area>0.2</area>
          <air_density>1.2041</air_density>
          <forward>-1 0 0</forward>
          <upward>0 0 1</upward>
          <link_name>{$modelName}::Wing</link_name>
        </plugin -->

    </model>
</sdf>
